---
title: "백기선님과 함께 하는 자바 스터디 - 09"
author: "yeoji21"
date: 2021-08-21
categories: [Backend, Java]
tags: [java, java study, 자바, 자바 스터디]
pin: true
---

<img src="https://media.vlpt.us/images/inhalin/post/b48b4cd3-619b-4bf4-939c-d3546dd2ec01/whiteship.png">

## 들어가면서
백기선님이 진행하신 자바 스터디 강의와 스터디에 참여하신 분들의 자료를 참고하여 작성한 글입니다.  
강의 영상 링크 : [[자바 라이브 스터디] 2020/1/16, 9주차 예외
](https://www.youtube.com/watch?v=ULKUslGh8cg&list=PLfI752FpVCS96fSsQe2E3HzYTgdmbz6LU&index=18)  
강의 깃허브 링크 : [9주차 과제: 예외 처리](https://github.com/whiteship/live-study/issues/9)

## 목차
- 자바에서 예외 처리 방법 (try, catch, throw, throws, finally)
- 자바가 제공하는 예외 계층 구조
- Exception과 Error의 차이는?
- RuntimeException과 RE가 아닌 것의 차이는?
- 커스텀한 예외 만드는 방법

### **Exception과 Error의 차이는?**

자바에서 에러는 크게 `컴파일 에러`와 `런타임 에러`로 나뉜다.  
컴파일 에러는 말 그대로 컴파일 시에 발생하는 에러를 말하고, 런타임 에러는 런타임 시에 발생하는 에러를 말한다.  

**컴파일 에러**는 자바 컴파일러가 문법 검사를 통해 오류를 미리 잡아준다. IDE에서 코드를 작성할 때 빨간줄이 뜨면서 컴파일 에러를 경고해주는 것을 본 적이 있을 것이다.  

그러나 컴파일이 문제없이 되더라도 실행 과정에서 **런타임 에러**가 발생할 수 있다. 런타임 에러는 프로그램 실행 중에 일어날 수 있는 모든 경우의 수를 고려하여 대비할 필요가 있다.  

자바에서는 런타임 에러를 예외(Exception)와 에러(Error)로 구분하고 있다. 클래스 계층구조는 아래와 같다.  

<img src="https://github.com/ByungJun25/study/raw/main/java/whiteship-study/9week/Throwable.png" width=600> 

출처 : <https://github.com/ByungJun25/study/tree/main/java/whiteship-study/9week>

`Error`는 메모리 부족(OutOfMemoryError), 스택 오버플로우(StackOverFlowError)처럼 JVM이나 하드웨어 등 시스템 레벨 상의 문제로 인해 발생한다. 에러가 발생하면 프로그램은 무조건 비정상 종료되기 때문에 애초에 발생하지 않도록 해야 한다.  

`Exception`은 프로그램 상의 오류로 인해 발생하는 프로그램 오류이다. 발생하더라도 미리 적절한 코드를 작성하여 프로그램이 비정상적으로 종료되지 않도록 핸들링할 수 있으며 이를 예외 처리라고 한다. 

### **자바에서 예외 처리 방법 (try, catch, throw, throws, finally)** 

#### try-catch 블럭

예외처리(Exception Handling)이란, 프로그램 실행 시 발생할 수 있는 예기치 못한 예외의 발생을 대비한 코드를 작성하는 것이며, 예외처리의 목적은 예외의 발생으로 인한 실행 중인 프로그램의 갑작스러운 비정상 종료를 막고, 실행상태를 유지하도록 하기 위함이다.  

만약 발생한 예외를 처리하지 못하면, 처리되지 못한 예외(uncaught exception)는 JVM의 `예외 처리기(UncaughtExceptionHandler)`가 받아서 해당 예외가 담고있던 `Stack Trace`를 출력하면서 프로그램이 종료된다. 

```java
try{
    System.out.println("try-catch 예제");
    System.out.println(10 / 0);
    System.out.println("예외 발생 시 이 문장은 실행되지 않음");
}catch(ArithmeticException e){
    System.out.println("정수형을  0으로 나누면 에러 발생");
}
```
```console
try-catch 예제
정수형을  0으로 나누면 에러 발생
```

위 코드는 정수를 0으로 나누기 때문에 `ArithmeticException`이 발생한다. try 블럭 내에서 예외가 발생하면, 즉시 try 블럭을 나와서 ArithmeticException을 처리할 수 있는 catch 블럭이 존재하는지 찾는다.  

만약 적절한 catch 블럭을 찾았다면 catch 블럭 내 코드를 실행한 다음 try-catch문을 벗어난다. 따라서 위 코드는 예외가 발생했지만 적절한 예외처리를 통해 정상종료되었다.

```java
try{
    System.out.println("try-catch 예제");
    System.out.println(10 / 0);
    System.out.println("예외 발생 시 이 문장은 실행되지 않음");
}catch(NumberFormatException e1){
    System.out.println("NumberFormatException 발생");
}
catch(ArithmeticException e2){
    System.out.println("ArithmeticException 발생");
}
catch(Exception e3){
    System.out.println("Exception 발생");
}
```
하나의 try 블럭에 대해 여러 종류의 예외를 처리할 수 있도록 여러 개의 catch 블럭을 사용할 수도 있다. 이 중에서 발생한 예외의 종류와 일치하는 단 하나의 catch 블럭만 수행된다. 
> 이 때 try 블럭에서 발생한 실제 예외와 catch 블럭의 예외를 `instanceof` 연산자를 통해 검사한다. 

이 때 주의해야할 것은 위의 catch 블럭에서 걸리면 아래 catch 블럭은 호출되지 않는다는 점이다. 그렇기때문에 예를 들어 위에 블럭에 `RuntimeException`을 잡아놓고, 그 밑에 `IllegalArgumentException`을 잡아놨다면 잘못된 코드이다. 이런 경우가 발생하면 IDE에서 에러로 알려준다. 

#### 멀티 catch 블럭
JDK 1.7부터 여러 catch 블럭에 대해 같은 처리를 할 때 `|`기호를 통해 하나의 catch 블럭으로 합칠 수 있게 되었다. 이를 멀티 catch 블럭이라 하며 합칠 수 있는 예외 클래스의 개수는 제한이 없다.

```java
catch(NumberFormatException | ArithmeticException e){
    System.out.println("Exception 발생");
    e.printStackTrace():
}
```

하지만 이 때 `|`로 연결된 두 예외 클래스가 조상과 자손 관계라면 컴파일 에러가 발생하므로 주의해야 한다.

#### 예외 발생시키기 throw
키워드 `throw`를 사용해 고의로 예외를 발생시킬 수 있다.
```java
try{
    throw new Exception("고의로 만든 예외");
}
catch(Exception e){
    System.out.println("Exception 발생");
}
```

이 것을 이용하여 예외를 잡아서(catch) 다른 예외를 던지는 **예외 전환**을 사용할 수도 있다. 호출한 쪽에서 예외를 받아서 처리할 떄 좀 더 명확하게 인지할 수 있도록 돕기 위한 방법이다. 

또한, `CheckedException` 중 복구가 불가능한 예외가 잡혔다면 어쩔 수 없이 의미없는 `try-catch`문을 추가해야하는데, 이 때 `UncheckedException`으로 전환해서 던져버릴 수도 있다. 

```java
try{
	...
}
catch(SQLException e){
	throw DuplicateUserIdException();
}
```

#### 메소드에 예외 선언하기 throws
`throws` 키워드로 메소드에 예외를 선언할 수 있다. 
```java
void method() throws Exception1, Exception2, ... , ExceptionN{
    ...
}
```
이렇게 메소드의 선언부에 예외를 선언함으로써 해당 메소드에서 어떠한 예외가 처리되어야 하는지 직관적으로 파악할 수 있다.  

하지만 이렇게 메소드에 예외를 선언한다고 해서 예외가 처리되는 것은 아니고, 해당 메소드를 **호출한 메소드에게 예외를 던져서 예외처리를 떠넘기는 것**이다.  

단순히 예외를 넘길 뿐이므로 어느 한 곳에서도 예외처리를 해주지 않으면 결국 main 메소드에게 예외가 넘어가 프로그램이 종료된다. 
```java
public static void main(String[] args) throws Exception {
    method1();
}
static void method1() throws Exception {
    method2();
}
static void method2() throws Exception {
    throw new Exception("method2()에서 예외 발생");
}
```
```console
Exception in thread "main" java.lang.Exception: method2()에서 예외 발생
	at com.example.javastudy.week9.ExceptionTest.method2(ExceptionTest.java:11)
	at com.example.javastudy.week9.ExceptionTest.method1(ExceptionTest.java:8)
	at com.example.javastudy.week9.ExceptionTest.main(ExceptionTest.java:5)
```
실행 결과를 보면, 프로그램 실행 중 `java.lang.Exception`이 발생하여 비정상적으로 종료되었다는 사실과 예외 발생 시 `call stack`의 내용을 알 수 있다.

```java
public static void main(String[] args) {
    try {
        method1();
    } catch (Exception e) {
        System.out.println("main 메소드에서 대신 예외처리");
    }
}
static void method1() throws Exception {
    method2();
}
static void method2() throws Exception {
    throw new Exception("method2()에서 예외 발생");
}
```

이렇게 예외를 main에서 처리하거나 method2()를 호출하는 method1()에서 처리할 수도 있다.

#### finally 블럭
`finally`는 try-catch문에서 예외의 발생여부와 상관없이 실행되어야 할 코드를 포함하는 목적으로 사용한다. try-catch문의 맨 끝에 한 번만 선언할 수 있기때문에, **try-catch-finally**의 순서로 구성된다.  

따라서 finally 블럭은 예외의 발생하던 말던 실행된다. 심지어 try 블럭이나 catch 블럭에 `return`문이 있더라도 finally문이 실행된다.

```java
public static void main(String[] args) {
    method();
    System.out.println("method1()가 복귀한 후 실행될 문장");
}
static void method(){
    try {
        System.out.println("try block");
        return;
    } catch (Exception e) {
        System.out.println("catch block");
    }finally{
        System.out.println("finally block");
    }
}
```
```console
try block
finally block
method1()가 복귀한 후 실행될 문장
```

그렇기 때문에 **finally 블럭 내에서 return문을 사용하는 것은 안티패턴**이므로 사용하지 않아야 한다. 만약 try문과 catch문에서 return을 호출하고 싶어도 항상 finally의 return이 호출되기 때문에 프로그램이 의도치 않은 흐름으로 동작할 수 있기 때문이다.  

따라서 finally문에서는 흐름을 바꾸는 코드의 사용은 지양하고, 자원 반납이나 로깅 등의 용도로 사용해야 한다.

#### 자원 자동 반환 try-with-resource문
Java 7부터 자원 반납을 자동으로 해주는 `try-with-resource` 기능이 추가되었다. 원래 FileInput이나 DB 커넥션 등은 자원을 사용한 뒤 finally 블럭을 통해 자원을 반납했는데, 이 방식은 몇 가지 문제점을 가지고 있었다.  

```java
void copy(String src, String dest) throws IOException {
    InputStream in = null;
    OutputStream out = null;
    try{
        in = new FileInputStream(src);
        out = new FileOutputStream(dest);
        byte[] buffer = new byte[1024];
        int n;
        while((n = in.read(buffer))>=0)
            out.write(buffer, 0, n);
    }finally{
        if(in != null) in.close();
        if(out != null) out.close();
    }
}
```
위 코드는 src로 받은 파일의 내용을 dest 파일로 복사하는 메소드 copy()를 나타낸다. 이 코드는 컴파일 에러가 잡히지 않지만, 문제점이 존재한다.   

바로 finally 블럭에 존재하는 `close()`에서 예외가 발생할 수도 있다는 점이다. 만약 `in.close()`에서 exception이 발생한다면 `out.close()`는 실행되지 않는다. 이건 위 아래 순서를 바꿔도 마찬가지일 것이다.  

그렇다면 finally 블럭 안에서도 try-catch를 통해 예외를 잡아주어야 할 것이다.  
```java
finally{
    if(in != null){
        try{
            in.close();
        }catch(IOException e){
            System.out.println("catch IOException in in.close()");
        }
    }
    if(out != null){
        try{
            out.close();
        }catch(IOException e){
            System.out.println("catch IOException in out.close()");
        }
    }
}
```
자, finally 블럭에도 각각 try-catch를 통해 예외처리를 해주었다. 근데 이 코드도 문제가 있다. `in.close()`에서 `IOException`이 아니라 `RuntimeException`이 발생한다면? 이런 경우에도 처음 코드처럼 밑에 있는 `out.close()`가 실행되지 않는다.  

그래서 이 것까지 고려하면 코드를 이렇게 짜야한다.  
```java
void copy(String src, String dest) throws IOException {
    InputStream in = null;
    OutputStream out = null;
    try{
        out = new FileOutputStream(dest);
        try{
            in = new FileInputStream(src);
            byte[] buffer = new byte[1024];
            int n;
            while((n = in.read(buffer)) >=0 )
                out.write(buffer, 0, n);
        }finally{
            if (in != null) {
                try{
                    in.close();
                }catch(IOException e){
                    System.out.println("catch IOException in in.close()");
                }
            }
        }
    }finally{
        if (out != null) {
            try{
                out.close();
            }catch(IOException e){
                System.out.println("catch IOException in out.close()");
            }
        }
    }
}
```
이런 말하기 뭐하지만 코드가 정말 더럽다. 하지만 Java 7 이후로는 `try-with-resource`문을 사용하여 간단하게 처리할 수 있게 되었다.  

```java
void copy(String src, String dest) throws IOException {
    try(InputStream in = new FileInputStream(src);
        OutputStream out = new FileOutputStream(dest)){
        byte[] buffer = new byte[1024];
        int n;
        while((n = in.read(buffer)) >= 0)
            out.write(buffer, 0, n);
    }
}
```
정말 간단하고 직관적이지 않은가? 위 코드에서는 예외를 던지고 있지만 copy 메소드에서 처리하고 싶으면 catch 블럭을 추가해서 예외를 잡아주면 된다.  

또한 finally블럭을 추가하면 자동 자원 반납 후 finally 블럭 실행하도록 할 수도 있다.
왜냐하면 `try-with-resource문`은 **내부적으로 catch문을 추가**해서 자동으로 자원반납해주기때문에 finally 블럭도 사용할 수 있다. 

그런데, 내부적으로 catch 블럭을 추가한다면 예외 상황에만 자원이 반납되는거 아닌가? 하는 의문이 들 수 있는데, 컴파일된 파일을 보면 catch문 안과 밖에 두 개의 `close()`가 있어서 예외가 발생하던 안하던 자원을 반납하도록 구성되어 있다.

try-with-resource문은 개발자의 실수를 줄여주고 코드를 훨씬 직관적이고 간단하게 구성할 수 있도록 한다. 따라서 Java 7 이후의 환경이라면 자원 반납 시 finally문 대신 try-with-resource문을 사용할 것을 적극 권장한다. 

#### 예외처리 비용
예외를 사용한다는 자체가 비용이 비싸다고 할 수 있다. `try-catch`를 동작하면서 발생하는 검사들도 하나의 원인이지만, `Throwable` 클래스의 생성자에 있는 `fillInStackTrace()` 메소드가 주 원인이다.  

이 메소드는 예외가 발생한 메소드의 `Stack Trace`를 모두 출력해주기 때문에 메모리를 많이 잡아먹는다. 따라서 로직으로 충분히 처리할 수 있다면 Exception을 사용하지 않는 것이 좋다.

### **자바가 제공하는 예외 계층 구조**
자바에서는 실행 시 발생할 수 있는 오류(Exception & Error)를 클래스로 정의하고 있다. 따라서 오류 또한 `Object` 클래스를 상속받고 있음을 추측할 수 있고, 실제 상속 계층도는 아래와 같다.  

<img src="https://user-images.githubusercontent.com/70433341/104199159-6d2f1200-546a-11eb-89bd-207c4d2c149f.png">

출처 : <https://catch-me-java.tistory.com/46>

맨 위에 자바의 최상위 클래스인 `Object` 클래스가 있고 그 것을 상속하는 예외 클래스의 최상위 클래스인 `Throwable` 클래스가 있다. Throwable 클래스는 모든 Exception과 Error의 부모 클래스이다.  

예외 처리 시 많이 사용하는 메소드인 `printStackTrace()`와 `getMessage()`가 바로 Throwable 클래스의 메소드이다. 

```java
public static void main(String[] args){
    try {
        throw new Exception("예외 메시지 작성");
    } catch (Exception e) {
        System.out.println("에러 메시지 : " + e.getMessage());
        e.printStackTrace();
    }
    System.out.println("정상 종료");
}
```
```console
에러 메시지 : 예외 메시지 작성
정상 종료
java.lang.Exception: 예외 메시지 작성
	at com.example.javastudy.week9.ExceptionTest.main(ExceptionTest.java:8)

Process finished with exit code 0
```

이렇게 예외타입의 매개변수에 `printStackTrace()`를 호출하게 되면 예외가 발생하기 까지의 이력을 출력해준다. 이 이력은 어디에 저장되었다가 출력되는 것일까?  

1주차에서 배운 JVM의 구조를 떠올려보면, 메소드 실행 시 메모리의 `Stack` 영역에 `Stack Frame`이 쌓이게 된다. 즉, Stack 영역은 Stack Frame을 저장하는 영역이며, JVM은 오직 Stack Frame을 `push`하고 `pop`하는 작업을 한다.  

예외가 발생 시에 출력되는 Stack Trace의 각 라인은 Stack Frame을 표현하는 것이며, 메모리 영역 Stack에 쌓여있는 Stack Frame들을 pop하며 출력하는 것이다. 

<br>
예외 클래스의 최상위 클래스는 항상 Throwable 클래스이지만, 세부적으로 들어가 보면 이를 상속하는 예외는 크게 세 가지 부류로 나뉜다. 

1. Error 클래스를 상속하는 예외 클래스
2. RuntimeException 클래스를 상속하는 Exception 클래스
3. RuntimeException 클래스를 상속하지 않는 Exception 클래스

앞서 Error와 Exception의 차이는 언급했기 때문에 알고 있지만, Exception을 상속하는 클래스들 중에서도 RuntimeException을 상속한 클래스와 그렇지 않은 클래스 간에는 어떠한 차이가 존재할까?

### **RuntimeException과 RE가 아닌 것의 차이는?**
RuntimeException을 상속한 클래스는 `Unchecked Exception`이라고 하고, RuntimeException을 상속하지 않은 Exception 클래스는 `Checked Exception`이라고 한다.  

#### **CheckedException**
`CheckedException`은 컴파일 시점에 확인될 수 있는(체크될 수 있는) 예외를 말한다. 즉, 프로그램 내부의 로직이 아닌 프로그램의 제어 밖에서 발생하는 오류를 의미한다. 따라서 CheckedException이 발생하는 코드를 실행하기 위해서는 **반드시 예외처리(try-catch나 throws)를 해줘야 한다.**  

#### CheckedException의 대표적인 예시
1. IOException  
    `IOException`은 input이나 output 작업이 실패할 때 발생하는 예외이다. IOException를 상속한 클래스로는 `FileNotFoundException`, `MalformedURLException` 등이 있다.

    ```java
    public class IOExceptionExample {
        public static void main(String[] args) {
            try (FileReader reader = new FileReader("invalidFileName")) {
            /...
            } catch (FileNotFoundException e) {
                System.out.println("FileNotFoundException 발생");
            } catch (IOException e) {
                System.out.println("IOException 발생");
            }
        }
    }
    ```
2. ParseException  
    `ParseException`은 텍스트를 파싱하는 작업이 실패할 때 발생한다.

    ```java
    public class ParseExceptionExample {
        public static void main(String[] args) {
            try {
                new SimpleDateFormat("MM-dd-yyyy").parse("test");
            } catch (ParseException e) {
                System.out.println("ParseException 발생");
            }
        }
    }
    ```
3. InterruptedException  
    `InterruptedException`은 다른 쓰레드가 `wating` 혹은 `timed_wating` 상태인 쓰레드에 `interrupt` 할 때 발생하는 예외이다. 

    ```java
    public class InterruptedExceptionExample {
        public static void main(String[] args) {
            subThread subThread = new subThread();
            subThread.start();
            subThread.interrupt();
        }

        public static class subThread extends Thread {
            @Override
            public void run() {
            try {
                Thread.sleep(10000); // 10초간 sleep
            } catch (InterruptedException e) {
                System.out.println("InterruptedException 발생");
            }
            }
        }
    }
    ```

#### **UncheckedException**
`UncheckedException`은 프로그램 상의 문제로 인해 실행 시(Runtime)에 발생하는 오류를 의미한다. 자바는 컴파일 시점에 UncheckedException을 확인하지 않기 때문에 **예외 처리를 강제하지 않는다.** 따라서 이 것을 핸들링할지 말지는 사용자가 정해야 한다. 

#### UncheckedException의 대표적인 예시
1. NullPointException  
    `NullPointException`은 객체를 필요로 하는 곳에서 null값을 참조할 때 발생한다. 
    ```java
    public class Example {
        public static void main(String[] args) {
            String text = null;
            text.length(); // NullPointerException 발생
        }
    }
    ```
2. ArrayIndexOutOfBoundsException  
    `ArrayIndexOutOfBoundsException`은 범위를 넘어선 잘 못된 인덱스에 접근할 때 발생한다.  

    ```java
    public class Example {
        public static void main(String[] args) {
            int[] numbers = new int[5];
            int number = numbers[5]; // ArrayIndexOutOfBoundsException 발생
        }
    }   
    ```
3. StringIndexOutOfBoundsException  
    `StringIndexOutOfBoundsException`은 텍스트의 길이보다 크거나 같은 인덱스에 접근할 때 발생한다. 

    ```java
    public class Example {
        public static void main(String[] args) {
            String text = "Test text";
            text.charAt(9); // StringIndexOutOfBoundsException 발생
        }
    }
    ```
4. NumberFormatException  
    `NumberFormatException`은 텍스트가 변환하고자하는 숫자 데이터 형식에 맞지 않을 때 발생한다.  

    ```java
    public class Example {
        public static void main(String[] args) {
            int number = Integer.parseInt("12Ab3C"); // NumberFormatException 발생
        }
    }
    ```

5. ArithmeticException  
    `ArithmeticException`은 산술연산 시 해당 연산이 잘못된 조건일 때 발생한다. 

    ```java
    public class Example {
        public static void main(String[] args) {
            System.out.println(5/0); // ArithmeticException 발생
        }
    }
    ```

6. ClassCastException  
    `ClassCastException`은 객체를 다운캐스팅할 때, 잘못된 인스턴스를 캐스팅하여 발생한다.  

    ```java
    class Monster{}
    class Digimon extends Monster{}
    class Pocketmon extends Monster{}

    public class ExceptionTest {
        public static void main(String[] args){
            Monster a = new Digimon();
            Pocketmon b = (Pocketmon) a; // ClassCastException 발생
        }
    }
    ``` 

7. IllegalArgumentException  
    `IllegalArgumentException`은 메소드에 잘못된 변수를 전달할 때 발생한다. 

    ```java
    public class Example {
        public static void main(String[] args) {
            Thread.sleep(-1); // IllegalArgumentException 발생
        }
    }
    ```

8. IllegalStateException  
    `IllegalStateException`은 메소드를 잘못된 시점에 호출했을 때 발생한다.  

    ```java
    public class Example {
        public static void main(String[] args) {
            ListIterator<Object> it = new ArrayList<>().listIterator();
            it.remove(); // IllegalStateException 발생
        }
    }
    ```

이렇게 UncheckedException의 경우 컴파일러가 체크 해주지 않기 때문에, 혼란을 방지하기 위해서는 이 메소드에 Exception이 있다는 것을 알리는 편이 좋다.  

`javadoc`을 이용하면 이것을 간단하게 표시할 수 있다. javadoc의 `@throws`와 `@exception` 키워드를 통해 메소드 내의 Exception에 대한 설명을 추가하도록 하자.

```java
/** 
 * @throws Exception explanation
 * @exception IllegalArgumentException explanation
*/
public void method() throws Exception {
  throw new IllegalArgumentException();
}
```

#### exception을 분리한 이유 

예외는 메소드의 파라미터나 리턴 타입만큼이나 중요한 공용 인터페이스 중 하나이다. 따라서 메소드를 호출하는 쪽은 해당 메소드가 어떤 예외를 발생시킬 수 있는지에 대해 반드시 알아야 한다.  

따라서 Java는 `CheckedException`을 통해 해당 메소드가 발생시킬 수 있는 예외를 명시하도록 강제하고 있다. 그런데 `RuntimeExcepton`은 왜 예외를 명시하지 않아도 되는 것일까?

RuntimeException은 프로그램 코드 상의 문제로 발생하는 예외이다.(개발자가 코드를 잘 못짜서 발생) 따라서 메소드를 호출하는 쪽(클라이언트)에서 이 예외를 복구하거나 대처할 수 있을 거라고 기대하기 힘들다.  

또한, RuntimeException은 프로그램 어디에서나 빈번하게 등장할 수 있기때문에 매 번 모든 RuntimeException을 명시하도록 하는 것은 오히려 프로그램의 명확성을 떨어뜨릴 수 있다. 

따라서 클라이언트가 exception을 적절히 대처할 수 있을 것이라고 예상되는 경우 CheckedException으로 만들고, 그렇지 않은 경우 UncheckedException으로 만드는 것이 좋다.


#### UncheckedException과 트랜젝션?
스터디를 진행하신 많은 분들의 과제에서 UncheckedException과 CheckedException에 대한 트렌잭션 처리에 관한 잘못된 정보가 있었다. 많은 포스트에서 `UncheckedException`이 발생하면 트렌잭션에 대해 `roll-back` 기능을 제공한다고 나와있는데, 이 것은 명백히 잘못된 정보이다.  

이 것은 순수 자바 언어에서 지원하는 기능이 아니라, `spring framework`에서 기본 설정으로 제공하는 기능이다. 따라서 이 것을 Java에서 지원하는 기능이라고 오해해서는 안되겠다.


### **커스텀한 예외 만드는 방법**

#### Custom Checked Exception
`Exception` 클래스를 상속하면 `Custom Checked Exception` 클래스를 만들 수 있다.  

```java
/**
 * this CustomException extends Exception and ....
 * @author yeoji
 */
class CustomException extends Exception {
    public CustomException() {
    }

    public CustomException(String message) {
        super(message);
    }

    public CustomException(String message, Throwable cause) {
        super(message, cause);
    }
}
```
```java
public class ExceptionTest {
    public static void main(String[] args) throws CustomException {
        method();
    }

    static void method() throws CustomException {
        throw new CustomException("custom", new Exception());
    }
}
```
```console
Exception in thread "main" com.example.javastudy.week9.CustomException: custom
	at com.example.javastudy.week9.ExceptionTest.method1(ExceptionTest.java:11)
	at com.example.javastudy.week9.ExceptionTest.main(ExceptionTest.java:7)
Caused by: java.lang.Exception
	... 2 more
```

이 코드를 보면 method()에서 `CustomException`을 호출할 때 생성자에 예외 메시지와 함께 `cause exception`을 전달한 것을 알 수 있다. 만약 예외 메시지만 담아서 던질 경우, 예외 발생의 원인을 찾기 힘든 피상적인 예외가 될 수 있다. 

따라서 커스텀 예외의 생성자 호출 시 근본 원인이 되는 cause exception을 함께 전달할 것을 권장한다. 
> 그러나 커스텀 예외가 root cause일 수도 있으니 필수는 아니고 권장사항일뿐이다.

#### Custom Unchecked Exception
마찬가지로 `RuntimeException`을 상속하면 `Custom Unchecked Exception` 클래스를 만들 수 있다. 

```java
/**
 * this CustomException extends RuntimeException and ....
 * @author yeoji
 */
class CustomException extends RuntimeException {
    public CustomException() {
    }

    public CustomException(String message) {
        super(message);
    }

    public CustomException(String message, Throwable cause) {
        super(message, cause);
    }
}
```

#### 커스텀 예외 생성 시 고려 사항  
1. **Always Provide a Benefit**   
    자바 표준 예외는 다양한 장점을 가진 기능들을 포함한다. 이미 JDK가 존재하는 예외들과 비교해 커스텀 예외가 가지는 장점이 없다면 커스텀 예외를 만드는 이유를 다시 생각해봐야 할 것이다.  
2. **Follow the Naming Convention**  
    자바 표준 예외의 이름은 모두 Exception으로 끝나는 것을 알 수 있다. 이러한 네이밍 규칙은 자바 생태계 전체에 적용되므로 커스텀 예외 클래스도 이 네이밍 규칙을 따르는 것이 좋다.  
3. **Provide javadoc Comments for Your Exception Class**  
    문서화되어 있지 않은 API는 사용하기 매우 어렵다. 협업을 하는 다른 개발자뿐 아니라 미래의 나를 위해서라도 javadoc에 커스텀 클래스의 발생 상황이나 의미를 기술해야 한다.  
4. **Provide a Constructor That Sets the Cause**  
    커스텀 예외를 던지기 전에 표준 예외를 Catch하는 케이스가 꽤 많다. 이러한 예외는 오류를 분석하는데 중요한 정보가 포함되어 있으므로 cause exception을 유지해야 한다.






### 참조
<https://wisdom-and-record.tistory.com/46>  
<https://catch-me-java.tistory.com/46>  
<https://www.notion.so/3565a9689f714638af34125cbb8abbe8>  
<https://yadon079.github.io/2021/java%20study%20halle/week-09>  
<https://github.com/ByungJun25/study/tree/main/java/whiteship-study/9week>  
